Workbook

Sheet Mulai
A2: SLR_09: review acuan penerimaan
A3: 50 narasi baru. Semua kategori, field dan token masih usulan; belum diuji model.
A5: Reviewer | B5: Bintang
A6: Target yang sudah disetujui | B6: DISETUJUI_PEMILIK
A8: Status review narasi | B8: Jumlah
A9: APPROVED | B9: =COUNTIF(Narasi!J6:J55,"APPROVED")
A10: DEFERRED | B10: =COUNTIF(Narasi!J6:J55,"DEFERRED")
A11: PENDING | B11: =COUNTIF(Narasi!J6:J55,"PENDING")
A12: Token yang disediakan | B12: =COUNTA(Token!A6:A697)
A14: Kelengkapan untuk impor | B14: =IF(AND(B5<>"",B9=50,B10=0,B11=0,MIN(B29:B33)>=10,MIN(B37:B50)>=1,COUNTBLANK(Token!D6:D697)=0),"SIAP VALIDASI","PERLU REVIEW ACUAN")
A16: Kandidat: SILAR_SENA_context_v0.8.4_20261020.zip
A17: Isi reviewer. Periksa Narasi dan Token, lalu pilih APPROVED atau DEFERRED per narasi.
A18: ID target | B18: Target | C18: Aturan | D18: Penilaian
A19: sena_macro_f1 | B19: 0.85 | C19: ≥ | D19: SENA macro F1
A20: non_event_recall | B20: 0.9 | C20: ≥ | D20: Recall NON_EVENT
A21: event_class_recall | B21: 0.8 | C21: ≥ | D21: Recall tiap kelas kejadian
A22: nara_macro_f1_all_14_non_o | B22: 0.75 | C22: ≥ | D22: NARA macro F1 semua 14 non-O
A23: nara_exact_span_f1 | B23: 0.6 | C23: ≥ | D23: NARA exact span F1
A24: fields_nonempty_exact | B24: 0.8 | C24: ≥ | D24: Ketepatan field nonkosong
A25: empty_field_spurious_rate_max | B25: 0.05 | C25: ≤ | D25: Isi berlebih pada field kosong
A28: Kategori yang disetujui | B28: Jumlah | C28: Minimum
A29: FLOOD | B29: =COUNTIFS(Narasi!C6:C55,"FLOOD",Narasi!J6:J55,"APPROVED") | C29: 10
A30: EARTHQUAKE | B30: =COUNTIFS(Narasi!C6:C55,"EARTHQUAKE",Narasi!J6:J55,"APPROVED") | C30: 10
A31: FIRE | B31: =COUNTIFS(Narasi!C6:C55,"FIRE",Narasi!J6:J55,"APPROVED") | C31: 10
A32: ACCIDENT | B32: =COUNTIFS(Narasi!C6:C55,"ACCIDENT",Narasi!J6:J55,"APPROVED") | C32: 10
A33: NON_EVENT | B33: =COUNTIFS(Narasi!C6:C55,"NON_EVENT",Narasi!J6:J55,"APPROVED") | C33: 10
A36: Role acuan non-O | B36: Token | C36: Minimum
A37: ACCIDENT-EVENT | B37: =COUNTIF(Token!D6:D697,"ACCIDENT-EVENT") | C37: 1
A38: AFFECTEDOBJECTS-ARG | B38: =COUNTIF(Token!D6:D697,"AFFECTEDOBJECTS-ARG") | C38: 1
A39: DEATHVICTIM-ARG | B39: =COUNTIF(Token!D6:D697,"DEATHVICTIM-ARG") | C39: 1
A40: EARTHQUAKE-EVENT | B40: =COUNTIF(Token!D6:D697,"EARTHQUAKE-EVENT") | C40: 1
A41: FALSE-EVENT | B41: =COUNTIF(Token!D6:D697,"FALSE-EVENT") | C41: 1
A42: FIRE-EVENT | B42: =COUNTIF(Token!D6:D697,"FIRE-EVENT") | C42: 1
A43: FLOOD-EVENT | B43: =COUNTIF(Token!D6:D697,"FLOOD-EVENT") | C43: 1
A44: INFORMATION-ARG | B44: =COUNTIF(Token!D6:D697,"INFORMATION-ARG") | C44: 1
A45: OFFICER-ARG | B45: =COUNTIF(Token!D6:D697,"OFFICER-ARG") | C45: 1
A46: PLACE-ARG | B46: =COUNTIF(Token!D6:D697,"PLACE-ARG") | C46: 1
A47: REASON-ARG | B47: =COUNTIF(Token!D6:D697,"REASON-ARG") | C47: 1
A48: STREET-ARG | B48: =COUNTIF(Token!D6:D697,"STREET-ARG") | C48: 1
A49: TIME-ARG | B49: =COUNTIF(Token!D6:D697,"TIME-ARG") | C49: 1
...

Sheet Narasi
A2: Acuan narasi dan field
A3: Kolom kuning perlu diperiksa. Pisahkan beberapa item pada field dengan tanda |.
A4: Status APPROVED mencakup kategori, seluruh field dan label token pada ID tersebut.
A5: ID | B5: Narasi | C5: Kategori | D5: Lokasi | E5: Waktu | F5: Pihak | G5: Dampak | H5: Korban | I5: Objek | J5: Status | K5: Catatan
A6: FINAL084-FLOOD-01 | B6: Subuh tadi, banjir menggenangi taman kota di Kelurahan Renggapada. | C6: FLOOD | D6: Kelurahan Renggapada | E6: Subuh tadi | G6: menggenangi taman kota | I6: taman kota | J6: APPROVED
A7: FINAL084-FLOOD-02 | B7: Di Desa Banyuarta, dua ruang kelas terendam banjir kemarin sore. | C7: FLOOD | D7: Desa Banyuarta | E7: kemarin sore | G7: dua ruang kelas terendam | I7: dua ruang kelas | J7: APPROVED
A8: FINAL084-FLOOD-03 | B8: Relawan desa mengevakuasi warga ketika banjir melanda Kampung Tirtawening malam tadi. | C8: FLOOD | D8: Kampung Tirtawening | E8: malam tadi | F8: Relawan desa | G8: mengevakuasi warga | J8: APPROVED
A9: FINAL084-FLOOD-04 | B9: Sesi latihan dihentikan: banjir betulan merendam ruang arsip di Balai Cendranusa siang ini. | C9: FLOOD | D9: Balai Cendranusa | E9: siang ini | G9: merendam ruang arsip | I9: ruang arsip | J9: APPROVED
A10: FINAL084-FLOOD-05 | B10: Petugas BPBD memverifikasi bahwa banjir di Dusun Larasbumi pagi ini benar terjadi, bukan cerita simulasi. | C10: FLOOD | D10: Dusun Larasbumi | E10: pagi ini | F10: Petugas BPBD | J10: APPROVED
A11: FINAL084-FLOOD-06 | B11: Banjir akibat tanggul jebol menutup jalan menuju terminal di Desa Purnatirta sejak malam tadi. | C11: FLOOD | D11: Desa Purnatirta | E11: sejak malam tadi | G11: menutup jalan menuju terminal | I11: jalan menuju terminal | J11: APPROVED
A12: FINAL084-FLOOD-07 | B12: Seorang warga terluka saat banjir di Kelurahan Nirmalaya sore tadi. | C12: FLOOD | D12: Kelurahan Nirmalaya | E12: sore tadi | F12: Seorang warga | H12: Seorang warga terluka | J12: APPROVED
A13: FINAL084-FLOOD-08 | B13: Banjir di Dusun Argalaras kemarin malam menyebabkan dua warga meninggal. | C13: FLOOD | D13: Dusun Argalaras | E13: kemarin malam | F13: dua warga | H13: dua warga meninggal | J13: APPROVED
A14: FINAL084-FLOOD-09 | B14: Pagar sekolah roboh diterjang banjir di Desa Sukmaraya pagi tadi; tidak ada korban. | C14: FLOOD | D14: Desa Sukmaraya | E14: pagi tadi | G14: Pagar sekolah roboh | I14: Pagar sekolah | J14: APPROVED
A15: FINAL084-FLOOD-10 | B15: Banjir masih menggenangi halaman rumah; lokasi dan waktunya tidak disebutkan. | C15: FLOOD | G15: menggenangi halaman rumah | I15: halaman rumah | J15: APPROVED
A16: FINAL084-EARTHQUAKE-01 | B16: Menjelang fajar, gempa mengguncang Kecamatan Puspareja. | C16: EARTHQUAKE | D16: Kecamatan Puspareja | E16: Menjelang fajar | G16: mengguncang | J16: APPROVED | K16: Dampak dikoreksi: Kecamatan Puspareja sudah dilabeli PLACE-ARG dan tercatat di Lokasi, jadi tidak diulang di Dampak.
A17: FINAL084-EARTHQUAKE-02 | B17: Tembok perpustakaan retak setelah gempa di Desa Rancawening siang kemarin. | C17: EARTHQUAKE | D17: Desa Rancawening | E17: siang kemarin | G17: Tembok perpustakaan retak | I17: Tembok perpustakaan | J17: APPROVED
A18: FINAL084-EARTHQUAKE-03 | B18: Usai gempa malam ini, tim penyelamat memeriksa bangunan di Kampung Candrabuana. | C18: EARTHQUAKE | D18: Kampung Candrabuana | E18: malam ini | F18: tim penyelamat | G18: memeriksa bangunan | J18: APPROVED
A19: FINAL084-EARTHQUAKE-04 | B19: Gempa sungguhan merusak langit-langit aula di Pusat Pelatihan Wanasari pagi tadi, tepat saat latihan berlangsung. | C19: EARTHQUAKE | D19: Pusat Pelatihan Wanasari | E19: pagi tadi | G19: merusak langit-langit aula | I19: langit-langit aula | J19: APPROVED
A20: FINAL084-EARTHQUAKE-05 | B20: Petugas kecamatan mengonfirmasi kejadian gempa di Desa Gunalaras tadi sore; kabar itu benar. | C20: EARTHQUAKE | D20: Desa Gunalaras | E20: tadi sore | F20: Petugas kecamatan | J20: APPROVED
A21: FINAL084-EARTHQUAKE-06 | B21: Aktivitas sesar memicu gempa yang merobohkan menara lonceng di Kelurahan Weningpada tengah malam tadi. | C21: EARTHQUAKE | D21: Kelurahan Weningpada | E21: tengah malam tadi | G21: merobohkan menara lonceng | I21: menara lonceng | J21: APPROVED
A22: FINAL084-EARTHQUAKE-07 | B22: Akibat gempa siang tadi di Desa Binarwangi, tiga pekerja terluka. | C22: EARTHQUAKE | D22: Desa Binarwangi | E22: siang tadi | F22: tiga pekerja | H22: tiga pekerja terluka | J22: APPROVED
A23: FINAL084-EARTHQUAKE-08 | B23: Seorang pedagang meninggal dalam gempa di Pasar Suralaras kemarin pagi. | C23: EARTHQUAKE | D23: Pasar Suralaras | E23: kemarin pagi | F23: Seorang pedagang | H23: Seorang pedagang meninggal | J23: APPROVED
A24: FINAL084-EARTHQUAKE-09 | B24: Tidak ada yang terluka, namun gempa merusak atap pos ronda di Dusun Padmanala sore ini. | C24: EARTHQUAKE | D24: Dusun Padmanala | E24: sore ini | G24: merusak atap pos ronda | I24: atap pos ronda | J24: APPROVED
A25: FINAL084-EARTHQUAKE-10 | B25: Gempa susulan terasa di Desa Jayanirmala sejak pagi; warga berkumpul di luar. | C25: EARTHQUAKE | D25: Desa Jayanirmala | E25: sejak pagi | F25: warga | G25: terasa | J25: APPROVED | K25: Label token susulan dikoreksi dari EARTHQUAKE-EVENT ke O; pemicu kejadian hanya kata gempa.
A26: FINAL084-FIRE-01 | B26: Kebakaran melalap gudang kain di Kampung Tanjunglaras dini hari ini. | C26: FIRE | D26: Kampung Tanjunglaras | E26: dini hari ini | G26: melalap gudang kain | I26: gudang kain | J26: APPROVED
A27: FINAL084-FIRE-02 | B27: Kemarin malam, tiga kios hangus akibat kebakaran di Jalan Weningkarya. | C27: FIRE | D27: Jalan Weningkarya | E27: Kemarin malam | G27: tiga kios hangus | I27: tiga kios | J27: APPROVED
A28: FINAL084-FIRE-03 | B28: Petugas damkar memadamkan api dalam kebakaran di Terminal Argatirta siang tadi. | C28: FIRE | D28: Terminal Argatirta | E28: siang tadi | F28: Petugas damkar | G28: memadamkan api | J28: APPROVED
A29: FINAL084-FIRE-04 | B29: Di tengah latihan, kebakaran nyata menghanguskan ruang genset di Gedung Sumanala sore tadi; latihan pun dihentikan. | C29: FIRE | D29: Gedung Sumanala | E29: sore tadi | G29: menghanguskan ruang genset | I29: ruang genset | J29: APPROVED
A30: FINAL084-FIRE-05 | B30: Regu pemadam memastikan kebakaran di Desa Kertawening pagi ini benar terjadi setelah kabarnya sempat dianggap hoaks. | C30: FIRE | D30: Desa Kertawening | E30: pagi ini | F30: Regu pemadam | J30: APPROVED
A31: FINAL084-FIRE-06 | B31: Hubungan pendek listrik menyebabkan kebakaran yang merusak panel kontrol di Pabrik Nusalestari malam tadi. | C31: FIRE | D31: Pabrik Nusalestari | E31: malam tadi | G31: merusak panel kontrol | I31: panel kontrol | J31: APPROVED
A32: FINAL084-FIRE-07 | B32: Kebakaran di Desa Rengganusa subuh tadi membuat dua penghuni terluka. | C32: FIRE | D32: Desa Rengganusa | E32: subuh tadi | F32: dua penghuni | H32: dua penghuni terluka | J32: APPROVED
A33: FINAL084-FIRE-08 | B33: Dalam kebakaran di Kelurahan Ciptalaras kemarin siang, seorang penjaga meninggal. | C33: FIRE | D33: Kelurahan Ciptalaras | E33: kemarin siang | F33: seorang penjaga | H33: seorang penjaga meninggal | J33: APPROVED
A34: FINAL084-FIRE-09 | B34: Kebakaran menghanguskan rak buku di Balai Weningrasa pagi tadi; seluruh penghuni selamat. | C34: FIRE | D34: Balai Weningrasa | E34: pagi tadi | G34: menghanguskan rak buku | I34: rak buku | J34: APPROVED
A35: FINAL084-FIRE-10 | B35: Sebuah bengkel hangus dalam kebakaran. Belum ada keterangan lokasi atau waktu. | C35: FIRE | G35: Sebuah bengkel hangus | I35: Sebuah bengkel | J35: APPROVED
A36: FINAL084-ACCIDENT-01 | B36: Kecelakaan melibatkan bus kota di Jalan Argawening pagi ini. | C36: ACCIDENT | D36: Jalan Argawening | E36: pagi ini | G36: melibatkan bus kota | I36: bus kota | J36: APPROVED
A37: FINAL084-ACCIDENT-02 | B37: Truk pasir terguling dalam kecelakaan di Jalan Puspakarya kemarin malam. | C37: ACCIDENT | D37: Jalan Puspakarya | E37: kemarin malam | G37: Truk pasir terguling | I37: Truk pasir | J37: APPROVED
A38: FINAL084-ACCIDENT-03 | B38: Polisi lalu lintas mengatur arus kendaraan usai kecelakaan di Jalan Suryanala siang tadi. | C38: ACCIDENT | D38: Jalan Suryanala | E38: siang tadi | F38: Polisi lalu lintas | G38: mengatur arus kendaraan | J38: APPROVED
A39: FINAL084-ACCIDENT-04 | B39: Latihan evakuasi terhenti oleh kecelakaan sungguhan: mobil katering terbalik di Jalan Nirmakarya sore ini. | C39: ACCIDENT | D39: Jalan Nirmakarya | E39: sore ini | G39: mobil katering terbalik | I39: mobil katering | J39: APPROVED
A40: FINAL084-ACCIDENT-05 | B40: Petugas kepolisian membenarkan laporan kecelakaan di Jalan Candralaras tadi malam; ini bukan adegan film. | C40: ACCIDENT | D40: Jalan Candralaras | E40: tadi malam | F40: Petugas kepolisian | J40: APPROVED
A41: FINAL084-ACCIDENT-06 | B41: Karena rem blong, kecelakaan merusak pagar jembatan di Jalan Wanasukma Raya pagi tadi. | C41: ACCIDENT | D41: Jalan Wanasukma Raya | E41: pagi tadi | G41: merusak pagar jembatan | I41: pagar jembatan | J41: APPROVED
...

Sheet Token
A2: Acuan token NARA
A3: Periksa label seluruh token untuk tiap ID. O berarti token di luar 14 role non-O.
A5: ID | B5: Posisi | C5: Token | D5: Label
A6: FINAL084-FLOOD-01 | B6: 1 | C6: Subuh | D6: TIME-ARG
A7: FINAL084-FLOOD-01 | B7: 2 | C7: tadi | D7: TIME-ARG
A8: FINAL084-FLOOD-01 | B8: 3 | C8: , | D8: O
A9: FINAL084-FLOOD-01 | B9: 4 | C9: banjir | D9: FLOOD-EVENT
A10: FINAL084-FLOOD-01 | B10: 5 | C10: menggenangi | D10: INFORMATION-ARG
A11: FINAL084-FLOOD-01 | B11: 6 | C11: taman | D11: AFFECTEDOBJECTS-ARG
A12: FINAL084-FLOOD-01 | B12: 7 | C12: kota | D12: AFFECTEDOBJECTS-ARG
A13: FINAL084-FLOOD-01 | B13: 8 | C13: di | D13: O
A14: FINAL084-FLOOD-01 | B14: 9 | C14: Kelurahan | D14: PLACE-ARG
A15: FINAL084-FLOOD-01 | B15: 10 | C15: Renggapada | D15: PLACE-ARG
A16: FINAL084-FLOOD-01 | B16: 11 | C16: . | D16: O
A17: FINAL084-FLOOD-02 | B17: 1 | C17: Di | D17: O
... A697: FINAL084-NON_EVENT-10 | B697: 17 | C697: . | D697: O
